<?xml version="1.0"?>
<robot name="turtlebot3_my_model" xmlns:xacro="http://ros.org/wiki/xacro">
    <xacro:include filename="$(find my_simulations)/urdf/common_properties.xacro"/>
    <xacro:include filename="$(find my_simulations)/urdf/turtlebot3_my_model.gazebo.xacro"/>

    <link name="base_footprint"/>

    <joint name="base_joint" type="fixed">
        <parent link="base_footprint"/>
        <child link="base_link" />
        <origin xyz="0 0 0.010" rpy="0 0 0"/>
    </joint>

    <!-- Deliver robot Base -->
    <link name="base_link">
        <visual>
            <!-- sdf 파일 참고해서 위치 설정 z축은 무시-->
            <origin xyz="0 0 0" rpy="0 0 0"/>
            <geometry>
                <box size="0.265 0.265 0.1"/>
            </geometry>
            <material name="light_black"/>
        </visual>

        <collision>
        <!-- sdf 파일 참고해서 위치 설정-->
        <origin xyz="0 0 0.06" rpy="0 0 0"/>
        <geometry>
            <!-- sdf 파일 참고해서 크기 설정-->
            <box size="0.265 0.265 0.1"/>
        </geometry>
        </collision>

        <inertial>
            <origin xyz="0 0 0" rpy="0 0 0"/>
            <mass value="1.3729096e+00"/>
            <inertia ixx="8.7002718e-03" ixy="-4.7576583e-05" ixz="1.1160499e-04"
                    iyy="8.6195418e-03" iyz="-3.5422299e-06"
                    izz="1.4612727e-02" />
        </inertial>
    </link>

    <!-- Deliver robot Left Wheel-->
    <!-- sdf 파일 참고해서 위치 설정-->
    <joint name="wheel_left_joint" type="continuous">
        <parent link="base_link"/>
        <child link="wheel_left_link"/>
        <origin xyz="0.07 0.11 0.033" rpy="-1.57 0 0"/>
        <axis xyz="0 0 1"/>
    </joint>   

    <link name="wheel_left_link">
        <visual>
            <origin xyz="0.07 0.11 0" rpy="-1.57 0 0"/>
            <geometry>
                <cylinder length="0.018" radius="0.033"/>
            </geometry>
            <material name="dark"/>
        </visual>

        <collision>
            <origin xyz="0.07 0.11 0" rpy="0 0 0"/>
            <geometry>
                <cylinder length="0.018" radius="0.033"/>
            </geometry>
        </collision>

        <inertial>
            <origin xyz="0 0 0" />
            <mass value="2.8498940e-02" />
            <inertia ixx="1.1175580e-05" ixy="-4.2369783e-11" ixz="-5.9381719e-09"
                    iyy="1.1192413e-05" iyz="-1.4400107e-11"
                    izz="2.0712558e-05" />
        </inertial>
    </link>  

    <!-- Deliver robot Right Wheel -->
    <joint name="wheel_right_joint" type="continuous">
        <parent link="base_link"/>
        <child link="wheel_right_link"/>
        <origin xyz="0.07 -0.11 0.033" rpy="-1.57 0 0"/>
        <axis xyz="0 0 1"/>
    </joint>

    <link name="wheel_right_link">
        <visual>
            <origin xyz="0.07 -0.11 0" rpy="1.57 0 0"/>
            <geometry>
                <cylinder length="0.018" radius="0.033"/>
            </geometry>
            <material name="dark"/>
        </visual>

        <collision>
            <origin xyz="0.07 -0.11 0" rpy="0 0 0"/>
            <geometry>
                <cylinder length="0.018" radius="0.033"/>
            </geometry>
        </collision>

        <inertial>
            <origin xyz="0 0 0" />
            <mass value="2.8498940e-02" />
            <inertia ixx="1.1175580e-05" ixy="-4.2369783e-11" ixz="-5.9381719e-09"
                    iyy="1.1192413e-05" iyz="-1.4400107e-11"
                    izz="2.0712558e-05" />
        </inertial>
    </link>

    <!-- Deliver robot Caster-->
    <joint name="caster_back_joint" type="fixed">
        <parent link="base_link"/>
        <child link="caster_back_link"/>
        <origin xyz="-0.11 0 0.005" rpy="-1.57 0 0"/>
    </joint>

    <link name="caster_back_link">
        <collision>
            <origin xyz="0 0.001 0" rpy="0 0 0"/>
            <geometry>
                <sphere radius="0.005"/>
            </geometry>
        </collision>

        <inertial>
            <origin xyz="0 0 0" />
            <mass value="0.005" />
            <inertia ixx="0.001" ixy="0.0" ixz="0.0"
                    iyy="0.001" iyz="0.0"
                    izz="0.001" />
        </inertial>
    </link>

    <!-- Deliver robot IMU-->
    <joint name="imu_joint" type="fixed">
        <parent link="base_link"/>
        <child link="imu_link"/>
        <origin xyz="0.0 0 0.076" rpy="0 0 0"/>
    </joint>

    <link name="imu_link"/>

    <!-- Deliver robot Caster-->
    <joint name="scan_joint" type="fixed">
        <parent link="base_link"/>
        <child link="base_scan"/>
        <origin xyz="0 0 0.141" rpy="0 0 0"/>
    </joint>

    <link name="base_scan">
        <visual>
            <origin xyz="0 0 0" rpy="0 0 0"/>
            <geometry>
                <mesh filename="package://turtlebot3_description/meshes/sensors/lds.stl" scale="0.001 0.001 0.001"/>
            </geometry>
            <material name="dark"/>
        </visual>

        <collision>
            <origin xyz="0.015 0 -0.0065" rpy="0 0 0"/>
            <geometry>
                <cylinder length="0.0315" radius="0.055"/>
            </geometry>
        </collision>

        <inertial>
            <mass value="0.114" />
            <origin xyz="0 0 0" />
            <inertia ixx="0.001" ixy="0.0" ixz="0.0"
                    iyy="0.001" iyz="0.0"
                    izz="0.001" />
        </inertial>
    </link>
</robot>