<?xml version="1.0" ?>
<!-- =================================================================================== -->
<!-- |    This document was autogenerated by xacro from /home/duckbe/catkin_ws/src/my_simulations/urdf/turtlebot3_my_model.urdf.xacro | -->
<!-- |    EDITING THIS FILE BY HAND IS NOT RECOMMENDED                                 | -->
<!-- =================================================================================== -->
<robot name="turtlebot3_my_model" xmlns:xacro="http://ros.org/wiki/xacro">
    <xacro:include filename="$(find my_simulations)/urdf/turtlebot3_my_model.gazebo.xacro"/>
    
    <link name="base_footprint" />

    <joint name="base_joint" type="fixed">
        <parent link="base_footprint" />
        <child link="base_link" />
        <origin rpy="0 0 0" xyz="0 0 0.06" />
        <!-- Initial point because child & parent link -->
    </joint>

    <!-- Deliver robot Base -->
    <link name="base_link">
        <visual>
            <!-- refer sdf (Initial point reference point)-->
            <origin rpy="0 0 0" xyz="0 0 0.0" />
            <geometry>
                <box size="0.265 0.265 0.1" />
            </geometry>
            <material name="light_black" />
        </visual>
        <collision>
            <!-- refer sdf(Initial point reference point) -->
            <origin rpy="0 0 0" xyz="0 0 0" />
            <geometry>
                <!-- refer sdf(Initial point reference point) -->
                <box size="0.265 0.265 0.1" />
            </geometry>
        </collision>
        
        <inertial>
            <origin rpy="0 0 0" xyz="0 0 0.0" />
            <mass value="1.5" />
            <inertia ixx="1.0028125e-2" ixy="0" ixz="0" iyy="1.0028125e-2" iyz="0" izz="1.755625e-02" />
        </inertial>
    </link>

    <!-- Deliver robot Caster-->
    <!-- refer sdf (Initial point reference point)-->
    <joint name="caster_back_joint" type="fixed">
        <parent link="base_link" />
        <child link="caster_back_link" />
        <origin rpy="0 0 0" xyz="0.11 0 -0.055" />
    </joint>

    <link name="caster_back_link">
        <visual>
            <!-- refer sdf (Initial point reference point)-->
            <origin rpy="0 0 0" xyz="0 0 0" />
            <geometry>
                <sphere radius="0.005" />
            </geometry>
            <material name="light_black" />
        </visual>
        <collision>
            <origin rpy="0 0 0" xyz="0 0 0" />
            <geometry>
                <sphere radius="0.005" />
            </geometry>
        </collision>
        
        <inertial>
            <origin xyz="0 0 0" />
            <mass value="0.005" />
            <inertia ixx="5.0e-8" ixy="0.0" ixz="0.0" iyy="5.0e-8" iyz="0.0" izz="5.0e-8" />
        </inertial>
    </link>

    <!-- Deliver robot Left Wheel-->
    <!-- refer sdf (Initial point reference point)-->
    <joint name="wheel_left_joint" type="continuous">
        <parent link="base_link" />
        <child link="wheel_left_link" />
        <origin rpy="-1.57 0 0" xyz="-0.07 0.11 -0.027" />
        <axis xyz="0 0 1" />
    </joint>

    <link name="wheel_left_link">
        <visual>
            <origin rpy="0 0 0" xyz="0 0 0" />
            <geometry>
                <cylinder length="0.018" radius="0.033" />
            </geometry>
            <material name="dark" />
        </visual>
        <collision>
            <origin rpy="0 0 0" xyz="0 0 0" />
            <geometry>
                <cylinder length="0.018" radius="0.033" />
            </geometry>
        </collision>
        
        <inertial>
            <origin xyz="0 0 0" />
            <mass value="2.8498940e-02" />
            <inertia ixx="1.083672194e-05" ixy="0" ixz="0" iyy="1.083672194e-05" iyz="0" izz="1.551767283e-05" />
        </inertial>
    </link>

    <!-- Deliver robot Right Wheel -->
    <!-- refer sdf (Initial point reference point)-->
    <joint name="wheel_right_joint" type="continuous">
        <parent link="base_link" />
        <child link="wheel_right_link" />
        <origin rpy="-1.57 0 0" xyz="-0.07 -0.11 -0.027" />
        <axis xyz="0 0 1" />
    </joint>

    <link name="wheel_right_link">
        <visual>
            <origin rpy="0 0 0" xyz="0 0 0" />
            <geometry>
                <cylinder length="0.018" radius="0.033" />
            </geometry>
            <material name="dark" />
        </visual>
        <collision>
            <origin rpy="0 0 0" xyz="0 0 0" />
            <geometry>
                <cylinder length="0.018" radius="0.033" />
            </geometry>
        </collision>
        
        <inertial>
            <origin xyz="0 0 0" />
            <mass value="2.8498940e-02" />
            <inertia ixx="1.083672194e-05" ixy="0" ixz="0" iyy="1.083672194e-05" iyz="0" izz="1.551767283e-05" />
        </inertial>
    </link>

    <!-- Deliver robot joint1-->
    <joint name="joint1_left_joint" type="revolute">
        <!--revolute have to limit-->
        <parent link="base_link" />
        <child link="joint1_left_link" />
        <origin rpy="-1.57 0 0" xyz="0.11 -0.135 0.04" />
        <axis xyz="0 0 1" />
        <!--Force, degree max min, velocity-->
        <limit effort="3" lower="-2.617" upper="2.617" velocity="0.05" />
    </joint>

    <link name="joint1_left_link">
        <visual>
            <origin rpy="0 0 0" xyz="0 0 0" />
            <geometry>
                <cylinder length="0.018" radius="0.015" />
            </geometry>
            <material name="dark" />
        </visual>
        <collision>
            <origin rpy="0 0 0" xyz="0 0 0" />
            <geometry>
                <cylinder length="0.018" radius="0.015" />
            </geometry>
        </collision>
        <visual>
            <origin rpy="0 0 0" xyz="0.05 0 0" />
            <geometry>
                <box size="0.1 0.03 0.03" />
            </geometry>
            <material name="dark" />
        </visual>
        <collision>
            <origin rpy="0 0 0" xyz="0.05 0 0" />
            <geometry>
                <box size="0.1 0.03 0.03" />
            </geometry>
        </collision>
        
        <inertial>
            <origin xyz="0.05 0 0" />
            <mass value="0.01" />
            <inertia ixx="1.6425e-6" ixy="0" ixz="0" iyy="1.6425e-6" iyz="0" izz="1.125e-6" />
        </inertial>
    </link>

    <joint name="joint1_right_joint" type="revolute">
        <parent link="base_link" />
        <child link="joint1_right_link" />
        <origin rpy="-1.57 0 0" xyz="0.11 0.135 0.04" />
        <axis xyz="0 0 1" />
        <limit effort="3" lower="-2.617" upper="2.617" velocity="0.05" />
    </joint>

    <link name="joint1_right_link">
        <visual>
            <origin rpy="0 0 0" xyz="0 0 0" />
            <geometry>
                <cylinder length="0.018" radius="0.015" />
            </geometry>
            <material name="dark" />
        </visual>
        <collision>
            <origin rpy="0 0 0" xyz="0 0 0" />
            <geometry>
                <cylinder length="0.018" radius="0.015" />
            </geometry>
        </collision>
        <visual>
            <origin rpy="0 0 0" xyz="0.05 0 0" />
            <geometry>
                <box size="0.1 0.03 0.03" />
            </geometry>
            <material name="dark" />
        </visual>
        <collision>
            <origin rpy="0 0 0" xyz="0.05 0 0" />
            <geometry>
                <box size="0.1 0.03 0.03" />
            </geometry>
        </collision>
        
        <inertial>
            <origin xyz="0.05 0 0" />
            <mass value="0.01" />
            <inertia ixx="1.6425e-6" ixy="0" ixz="0" iyy="1.6425e-6" iyz="0" izz="1.125e-6" />
        </inertial>
    </link>

    <!-- Deliver robot joint2-->
    <joint name="joint2_left_joint" type="revolute">
        <parent link="joint1_left_link" />
        <child link="joint2_left_link" />
        <origin rpy="0 0 0" xyz="0.1 0 0" />
        <axis xyz="0 0 1" />
        <limit effort="3" lower="-2.617" upper="2.617" velocity="0.05" />
    </joint>
    <link name="joint2_left_link">
        <visual>
            <origin rpy="0 0 0" xyz="0 0 0" />
            <geometry>
                <cylinder length="0.018" radius="0.015" />
            </geometry>
            <material name="dark" />
        </visual>
        <collision>
            <origin rpy="0 0 0" xyz="0 0 0" />
            <geometry>
                <cylinder length="0.018" radius="0.015" />
            </geometry>
        </collision>
        <visual>
            <origin rpy="0 0 0" xyz="0.05 0 0" />
            <geometry>
                <box size="0.1 0.03 0.03" />
            </geometry>
            <material name="dark" />
        </visual>
        <collision>
            <origin rpy="0 0 0" xyz="0.05 0 0" />
            <geometry>
                <box size="0.1 0.03 0.03" />
            </geometry>
        </collision>
        
        <inertial>
            <origin xyz="0.05 0 0" />
            <mass value="0.01" />
            <inertia ixx="1.6425e-6" ixy="0" ixz="0" iyy="1.6425e-6" iyz="0" izz="1.125e-6" />
        </inertial>
    </link>

    <joint name="joint2_right_joint" type="revolute">
        <parent link="joint1_right_link" />
        <child link="joint2_right_link" />
        <origin rpy="0 0 0" xyz="0.1 0 0" />
        <axis xyz="0 0 1" />
        <limit effort="3" lower="-2.617" upper="2.617" velocity="0.05" />
    </joint>
    <link name="joint2_right_link">
        <visual>
            <origin rpy="0 0 0" xyz="0 0 0" />
            <geometry>
                <cylinder length="0.018" radius="0.015" />
            </geometry>
            <material name="dark" />
        </visual>
        <collision>
            <origin rpy="0 0 0" xyz="0 0 0" />
            <geometry>
                <cylinder length="0.018" radius="0.015" />
            </geometry>
        </collision>
        <visual>
            <origin rpy="0 0 0" xyz="0.05 0 0" />
            <geometry>
                <box size="0.1 0.03 0.03" />
            </geometry>
            <material name="dark" />
        </visual>
        <collision>
            <origin rpy="0 0 0" xyz="0.05 0 0" />
            <geometry>
                <box size="0.1 0.03 0.03" />
            </geometry>
        </collision>
        
        <inertial>
            <origin xyz="0.05 0 0" />
            <mass value="0.01" />
            <inertia ixx="1.6425e-6" ixy="0" ixz="0" iyy="1.6425e-6" iyz="0" izz="1.125e-6" />
        </inertial>
    </link>

    <!-- Deliver robot IMU-->
    <joint name="imu_joint" type="fixed">
        <parent link="base_link" />
        <child link="imu_link" />
        <origin rpy="0 0 0" xyz="0.0 0 -0.048" />
    </joint>
    <link name="imu_link" />

    <!-- Deliver robot scan-->
    <joint name="scan_joint" type="fixed">
        <parent link="base_link" />
        <child link="base_scan" />
        <origin rpy="0 0 3.14" xyz="-0.012 0 0.08" />
    </joint>
    <link name="base_scan">
        <visual>
            <origin rpy="0 0 0" xyz="0 0 0" />
            <geometry>
                <mesh filename="package://turtlebot3_description/meshes/sensors/lds.stl" scale="0.001 0.001 0.001" />
            </geometry>
            <material name="dark" />
        </visual>
        <collision>
            <origin rpy="0 0 0" xyz="0.015 0 -0.0065" />
            <geometry>
                <cylinder length="0.0315" radius="0.055" />
            </geometry>
        </collision>
        
        <inertial>
            <mass value="0.114" />
            <origin xyz="0 0 0" />
            <inertia ixx="0.001" ixy="0.0" ixz="0.0" iyy="0.001" iyz="0.0" izz="0.001" />
        </inertial>
    </link>
    
    <transmission name="trans_joint1_left_joint">
        <type>transmission_interface/SimpleTransmission</type>
        <joint name="joint1_left_joint">
            <!--<hardwareInterface>hardware_interface/PositionJointInterface</hardwareInterface>-->
            <hardwareInterface>hardware_interface/EffortJointInterface</hardwareInterface>
        </joint>
        <actuator name="joint1_left_joint_motor">
            <!--<hardwareInterface>hardware_interface/PositionJointInterface</hardwareInterface>-->
            <hardwareInterface>hardware_interface/EffortJointInterface</hardwareInterface>
            <mechanicalReduction>1</mechanicalReduction>
        </actuator>
    </transmission>
    <transmission name="trans_joint1_right_joint">
        <type>transmission_interface/SimpleTransmission</type>
        <joint name="joint1_right_joint">
            <!--<hardwareInterface>hardware_interface/PositionJointInterface</hardwareInterface>-->
            <hardwareInterface>hardware_interface/EffortJointInterface</hardwareInterface>
        </joint>
        <actuator name="joint1_right_joint_motor">
            <!--<hardwareInterface>hardware_interface/PositionJointInterface</hardwareInterface>-->
            <hardwareInterface>hardware_interface/EffortJointInterface</hardwareInterface>
            <mechanicalReduction>1</mechanicalReduction>
        </actuator>
    </transmission>
    <transmission name="trans_joint2_left_joint">
        <type>transmission_interface/SimpleTransmission</type>
        <joint name="joint2_left_joint">
            <!--<hardwareInterface>hardware_interface/PositionJointInterface</hardwareInterface>-->
            <hardwareInterface>hardware_interface/EffortJointInterface</hardwareInterface>
        </joint>
        <actuator name="joint2_left_joint_motor">
            <!--<hardwareInterface>hardware_interface/PositionJointInterface</hardwareInterface>-->
            <hardwareInterface>hardware_interface/EffortJointInterface</hardwareInterface>
            <mechanicalReduction>1</mechanicalReduction>
        </actuator>
    </transmission>
    <transmission name="trans_joint2_right_joint">
        <type>transmission_interface/SimpleTransmission</type>
        <joint name="joint2_right_joint">
            <!--<hardwareInterface>hardware_interface/PositionJointInterface</hardwareInterface>-->
            <hardwareInterface>hardware_interface/EffortJointInterface</hardwareInterface>
        </joint>
        <actuator name="joint2_right_joint_motor">
            <!--<hardwareInterface>hardware_interface/PositionJointInterface</hardwareInterface>-->
            <hardwareInterface>hardware_interface/EffortJointInterface</hardwareInterface>
            <mechanicalReduction>1</mechanicalReduction>
        </actuator>
    </transmission>

</robot>