<?xml version="1.0"?>
<sdf version="1.5">
    <!-- Directory name must same model -->
    <model name="turtlebot3_my_model">
        <!-- Each model link name -->
        <link name="base">
            <!--choose center of mass, inertia, mass -->
            <inertial>
                <!-- center of mass pose -->
                <pose>0 0 0.06 0 0 0</pose>
                <inertia>
                    <ixx>0.001</ixx>
                    <ixy>0.000</ixy>
                    <ixz>0.000</ixz>
                    <iyy>0.001</iyy>
                    <iyz>0.000</iyz>
                    <izz>0.001</izz>
                </inertia>
                <mass>1.0</mass>
            </inertial>

            <!-- Deliver robot base -->
            <collision name="base_collision">
                <pose>0 0 0.06 0 0 0</pose>
                <geometry>
                    <box>
                        <!-- origin standpoint -->
                        <size>0.265 0.265 0.1</size>
                    </box>
                </geometry>
            </collision>
            
            <visual name="base_visual">
                <pose>0 0 0.06 0 0 0</pose>
                <geometry>
                    <box>
                        <size>0.265 0.265 0.1</size>
                    </box>
                </geometry>
            </visual>
            
            <collision name="caster_collision">
                <pose>-0.11 0 0.005 0 0 0</pose>
                <geometry>
                    <sphere>
                        <radius>0.005</radius>
                    </sphere>
                </geometry>
                <surface>
                    <friction>
                        <ode>
                            <mu>100000.0</mu>
                            <mu2>100000.0</mu2>
                            <fdir1>0 0 0</fdir1>
                            <slip1>0</slip1>
                            <slip2>0</slip2>
                        </ode>
                    </friction>
                </surface>
            </collision>

            <visual name="caster_visual">
                <pose>-0.11 0 0.005 0 0 0</pose>
                <geometry>
                    <sphere>
                        <radius>0.005000</radius>
                    </sphere>
                </geometry>
            </visual>
        </link>

<!--_____________________ Lidar ______________________-->

        <!-- Deliver robot lidar -->
        <link name="lidar">
            <inertial>
                <pose>0 0 0.13 0 0 0</pose>
                <inertia>
                    <ixx>0.001</ixx>
                    <ixy>0.000</ixy>
                    <ixz>0.000</ixz>
                    <iyy>0.001</iyy>
                    <iyz>0.000</iyz>
                    <izz>0.001</izz>
                </inertia>
                <mass>0.125</mass>
            </inertial>

            <collision name="lidar_sensor_collision">
                <pose>0 0 0.13 0 0 0</pose>
                <geometry>
                    <cylinder>
                        <radius>0.0508</radius>
                        <length>0.055</length>
                    </cylinder>
                </geometry>
            </collision>

            <visual name="lidar_sensor_visual">
                <pose>-0.012 0 0.14 0 0 0</pose>
                <geometry>
                    <mesh>
                        <uri>model://turtlebot3_burger/meshes/lds.dae</uri>
                        <scale>0.001 0.001 0.001</scale>
                    </mesh>
                </geometry>
            </visual>

            <sensor name="hls_lfcd_lds" type="ray">
                <always_on>1</always_on>
                <visualize>0</visualize>
                <pose>-0.012 0 0.14 0 0 0</pose>
                <update_rate>1800</update_rate>
                <ray>
                    <scan>
                        <horizontal>
                            <samples>360</samples>
                            <resolution>1.000000</resolution>
                            <min_angle>0.000000</min_angle>
                            <max_angle>6.280000</max_angle>
                        </horizontal>
                    </scan>
                    <range>
                        <min>0.120000</min>
                        <max>3.5</max>
                        <resolution>0.015000</resolution>
                    </range>
                    <noise>
                        <type>gaussian</type>
                        <mean>0.0</mean>
                        <stddev>0.01</stddev>
                    </noise>
                </ray>
            </sensor>
        </link> 

<!--_____________________ Wheel ______________________-->

        <!-- Deliver robot left wheel -->
        <link name="left_wheel">
            <inertial>
                <pose>0.07 0.11 0.033 -1.57 0 0</pose>
                <inertia>
                <ixx>0.001</ixx>
                <ixy>0.000</ixy>
                <ixz>0.000</ixz>
                <iyy>0.001</iyy>
                <iyz>0.000</iyz>
                <izz>0.001</izz>
                </inertia>
                <mass>0.1</mass>
            </inertial>

            <collision name="left_wheel_collision">
                <pose>0.07 0.11 0.033 -1.57 0 0</pose>
                <geometry>
                    <cylinder>
                        <radius>0.033</radius>
                        <length>0.018</length>
                    </cylinder>
                </geometry>
                <surface>
                    <friction>
                        <ode>
                            <mu>100000.0</mu>
                            <mu2>100000.0</mu2>
                            <fdir1>0 0 0</fdir1>
                            <slip1>0.0</slip1>
                            <slip2>0.0</slip2>
                        </ode>
                    </friction>
                </surface>
            </collision>

            <visual name="left_wheel_visual">
                <pose>0.07 0.11 0.033 -1.57 0 0</pose>
                <geometry>
                    <cylinder>
                        <radius>0.033</radius>
                        <length>0.018</length>
                    </cylinder>
                </geometry>
            </visual>
        </link>

        <!-- Deliver robot right wheel -->
        <link name="right_wheel">
            <inertial>
                <pose>0.07 -0.11 0.033 -1.57 0 0</pose>
                <inertia>
                    <ixx>0.001</ixx>
                    <ixy>0.000</ixy>
                    <ixz>0.000</ixz>
                    <iyy>0.001</iyy>
                    <iyz>0.000</iyz>
                    <izz>0.001</izz>
                </inertia>
                <mass>0.1</mass>
            </inertial>
            
            <collision name="right_wheel_collision">
                <pose>0.07 -0.11 0.033 -1.57 0 0</pose>
                <geometry>
                    <cylinder>
                        <radius>0.033</radius>
                        <length>0.018</length>
                    </cylinder>
                </geometry>
                <surface>
                    <friction>
                    <ode>
                        <mu>100000.0</mu>
                        <mu2>100000.0</mu2>
                        <fdir1>0 0 0</fdir1>
                        <slip1>0.0</slip1>
                        <slip2>0.0</slip2>
                    </ode>
                </friction>
                </surface>
            </collision>

            <visual name="right_wheel_visual">
                <pose>0.07 -0.11 0.033 -1.57 0 0</pose>
                <geometry>
                     <cylinder>
                        <radius>0.033</radius>
                        <length>0.018</length>
                    </cylinder>
                </geometry>
            </visual>
        </link>

<!--_____________________ Robot arm 1 ______________________-->

        <!-- Deliver robot joint_left 1 -->
        <link name="joint1_left">
            <inertial>
                <pose>-0.11 -0.135 0.1 1.57 0 0</pose>
                <inertia>
                    <ixx>0.001</ixx>
                    <ixy>0.000</ixy>
                    <ixz>0.000</ixz>
                    <iyy>0.001</iyy>
                    <iyz>0.000</iyz>
                    <izz>0.001</izz>
                </inertia>
                <mass>0.1</mass>
            </inertial>
            
            <collision name="joint1_left_collision">
                <pose>-0.11 -0.135 0.1 1.57 0 0</pose>
                <geometry>
                    <cylinder>
                        <radius>0.015</radius>
                        <length>0.018</length>
                    </cylinder>
                </geometry>
                <surface>
                    <friction>
                    <ode>
                        <mu>100000.0</mu>
                        <mu2>100000.0</mu2>
                        <fdir1>0 0 0</fdir1>
                        <slip1>0.0</slip1>
                        <slip2>0.0</slip2>
                    </ode>
                </friction>
                </surface>
            </collision>

            <visual name="joint1_left_visual">
                <pose>-0.11 -0.135 0.1 1.57 0 0</pose>
                <geometry>
                    <cylinder>
                        <radius>0.015</radius>
                        <length>0.018</length>
                    </cylinder>
                </geometry>
            </visual>
        </link>

        <!-- Deliver robot joint_right 1 -->
        <link name="joint1_right">    
            <inertial>
                <pose>-0.11 0.135 0.1 1.57 0 0</pose>
                <inertia>
                    <ixx>0.001</ixx>
                    <ixy>0.000</ixy>
                    <ixz>0.000</ixz>
                    <iyy>0.001</iyy>
                    <iyz>0.000</iyz>
                    <izz>0.001</izz>
                </inertia>
                <mass>0.1</mass>
            </inertial>   

            <collision name="joint1_right_collision">
                <pose>-0.11 0.135 0.1 1.57 0 0</pose>
                <geometry>
                    <cylinder>
                        <radius>0.015</radius>
                        <length>0.018</length>
                    </cylinder>
                </geometry>
                <surface>
                    <friction>
                    <ode>
                        <mu>100000.0</mu>
                        <mu2>100000.0</mu2>
                        <fdir1>0 0 0</fdir1>
                        <slip1>0.0</slip1>
                        <slip2>0.0</slip2>
                    </ode>
                </friction>
                </surface>
            </collision>

            <visual name="joint1_right_visual">
                <pose>-0.11 0.135 0.1 1.57 0 0</pose>
                <geometry>
                    <cylinder>
                        <radius>0.015</radius>
                        <length>0.018</length>
                    </cylinder>
                </geometry>
            </visual>
        </link>

        <!-- Deliver robot link1_left -->
        <link name="link1_left">
            <inertial>
                <pose>-0.16 0.135 0.1 0 0 0</pose>
                <inertia>
                    <ixx>0.001</ixx>
                    <ixy>0.000</ixy>
                    <ixz>0.000</ixz>
                    <iyy>0.001</iyy>
                    <iyz>0.000</iyz>
                    <izz>0.001</izz>
                </inertia>
                <mass>0.1</mass>
            </inertial>
            
            <collision name="link1_left_collision">
                <pose>-0.16 0.135 0.1 0 0 0</pose>
                <geometry>
                    <box>
                        <size>0.1 0.03 0.03</size>
                    </box>
                </geometry>
                <surface>
                    <friction>
                    <ode>
                        <mu>100000.0</mu>
                        <mu2>100000.0</mu2>
                        <fdir1>0 0 0</fdir1>
                        <slip1>0.0</slip1>
                        <slip2>0.0</slip2>
                    </ode>
                </friction>
                </surface>
            </collision>

            <visual name="link1_left_visual">
                <pose>-0.16 0.135 0.1 0 0 0</pose>
                <geometry>
                    <box>
                        <size>0.1 0.03 0.03</size>
                    </box>
                </geometry>
            </visual>
        </link>

        <!-- Deliver robot link1_right -->
        <link name="link1_right">
            <inertial>
                <pose>-0.16 -0.135 0.1 0 0 0</pose>
                <inertia>
                    <ixx>0.001</ixx>
                    <ixy>0.000</ixy>
                    <ixz>0.000</ixz>
                    <iyy>0.001</iyy>
                    <iyz>0.000</iyz>
                    <izz>0.001</izz>
                </inertia>
                <mass>0.1</mass>
            </inertial>
            
            <collision name="link1_right_collision">
                <pose>-0.16 -0.135 0.1 0 0 0</pose>
                <geometry>
                    <box>
                        <size>0.1 0.03 0.03</size>
                    </box>
                </geometry>
                <surface>
                    <friction>
                    <ode>
                        <mu>100000.0</mu>
                        <mu2>100000.0</mu2>
                        <fdir1>0 0 0</fdir1>
                        <slip1>0.0</slip1>
                        <slip2>0.0</slip2>
                    </ode>
                </friction>
                </surface>
            </collision>

            <visual name="link1_right_visual">
                <pose>-0.16 -0.135 0.1 0 0 0</pose>
                <geometry>
                    <box>
                        <size>0.1 0.03 0.03</size>
                    </box>
                </geometry>
            </visual>
        </link>

<!--_____________________ Robot arm 2 ______________________-->

        <!-- Deliver robot joint_left 2 -->
        <link name="joint2_left">
            <inertial>
                <pose>-0.21 -0.135 0.1 1.57 0 0</pose>
                <inertia>
                    <ixx>0.001</ixx>
                    <ixy>0.000</ixy>
                    <ixz>0.000</ixz>
                    <iyy>0.001</iyy>
                    <iyz>0.000</iyz>
                    <izz>0.001</izz>
                </inertia>
                <mass>0.1</mass>
            </inertial>
            
            <collision name="joint2_left_collision">
                <pose>-0.21 -0.135 0.1 1.57 0 0</pose>
                <geometry>
                    <cylinder>
                        <radius>0.015</radius>
                        <length>0.018</length>
                    </cylinder>
                </geometry>
                <surface>
                    <friction>
                    <ode>
                        <mu>100000.0</mu>
                        <mu2>100000.0</mu2>
                        <fdir1>0 0 0</fdir1>
                        <slip1>0.0</slip1>
                        <slip2>0.0</slip2>
                    </ode>
                </friction>
                </surface>
            </collision>

            <visual name="joint2_left_visual">
                <pose>-0.21 -0.135 0.1 1.57 0 0</pose>
                <geometry>
                    <cylinder>
                        <radius>0.015</radius>
                        <length>0.018</length>
                    </cylinder>
                </geometry>
            </visual>
        </link>

        <!-- Deliver robot joint_right 2 -->
        <link name="joint2_right">  
            <inertial>
                <pose>-0.21 0.135 0.1 1.57 0 0</pose>
                <inertia>
                    <ixx>0.001</ixx>
                    <ixy>0.000</ixy>
                    <ixz>0.000</ixz>
                    <iyy>0.001</iyy>
                    <iyz>0.000</iyz>
                    <izz>0.001</izz>
                </inertia>
                <mass>0.1</mass>
            </inertial>

            <collision name="joint2_right_collision">
                <pose>-0.21 0.135 0.1 1.57 0 0</pose>
                <geometry>
                    <cylinder>
                        <radius>0.015</radius>
                        <length>0.018</length>
                    </cylinder>
                </geometry>
                <surface>
                    <friction>
                    <ode>
                        <mu>100000.0</mu>
                        <mu2>100000.0</mu2>
                        <fdir1>0 0 0</fdir1>
                        <slip1>0.0</slip1>
                        <slip2>0.0</slip2>
                    </ode>
                </friction>
                </surface>
            </collision>

            <visual name="joint2_right_visual">
                <pose>-0.21 0.135 0.1 1.57 0 0</pose>
                <geometry>
                    <cylinder>
                        <radius>0.015</radius>
                        <length>0.018</length>
                    </cylinder>
                </geometry>
            </visual>
        </link>

        <!-- Deliver robot link2_left -->
        <link name="link2_left">
            <inertial>
                <pose>-0.26 0.135 0.1 0 0 0</pose>
                <inertia>
                    <ixx>0.001</ixx>
                    <ixy>0.000</ixy>
                    <ixz>0.000</ixz>
                    <iyy>0.001</iyy>
                    <iyz>0.000</iyz>
                    <izz>0.001</izz>
                </inertia>
                <mass>0.1</mass>
            </inertial>
            
            <collision name="link2_left_collision">
                <pose>-0.26 0.135 0.1 0 0 0</pose>
                <geometry>
                    <box>
                        <size>0.1 0.03 0.03</size>
                    </box>
                </geometry>
                <surface>
                    <friction>
                    <ode>
                        <mu>100000.0</mu>
                        <mu2>100000.0</mu2>
                        <fdir1>0 0 0</fdir1>
                        <slip1>0.0</slip1>
                        <slip2>0.0</slip2>
                    </ode>
                </friction>
                </surface>
            </collision>

            <visual name="link2_left_visual">
                <pose>-0.26 0.135 0.1 0 0 0</pose>
                <geometry>
                    <box>
                        <size>0.1 0.03 0.03</size>
                    </box>
                </geometry>
            </visual>
        </link>

        <!-- Deliver robot link2_right -->
        <link name="link2_right">
            <inertial>
                <pose>-0.26 -0.135 0.1 0 0 0</pose>
                <inertia>
                    <ixx>0.001</ixx>
                    <ixy>0.000</ixy>
                    <ixz>0.000</ixz>
                    <iyy>0.001</iyy>
                    <iyz>0.000</iyz>
                    <izz>0.001</izz>
                </inertia>
                <mass>0.1</mass>
            </inertial>
            
            <collision name="link2_right_collision">
                <pose>-0.26 -0.135 0.1 0 0 0</pose>
                <geometry>
                    <box>
                        <size>0.1 0.03 0.03</size>
                    </box>
                </geometry>
                <surface>
                    <friction>
                    <ode>
                        <mu>100000.0</mu>
                        <mu2>100000.0</mu2>
                        <fdir1>0 0 0</fdir1>
                        <slip1>0.0</slip1>
                        <slip2>0.0</slip2>
                    </ode>
                </friction>
                </surface>
            </collision>

            <visual name="link2_right_visual">
                <pose>-0.26 -0.135 0.1 0 0 0</pose>
                <geometry>
                    <box>
                        <size>0.1 0.03 0.03</size>
                    </box>
                </geometry>
            </visual>
        </link>

<!--_____________________ Joint ______________________-->

        <!-- link & link connection -->
        <joint name="left_wheel_joint" type="revolute">
            <parent>base</parent>
            <child>left_wheel</child>
            <pose>0.07 0.11 0.033 0 -1.57 0</pose>
            <axis>
                <xyz>0 1 0</xyz>
            </axis>
        </joint>

        <joint name="right_wheel_joint" type="revolute">
            <parent>base</parent>
            <child>right_wheel</child>
            <pose>0.07 -0.11 0.033 0 -1.57 0</pose>
            <axis>
                <xyz>0 1 0</xyz>
            </axis>
        </joint>

        <joint name="lidar_joint" type="fixed">
            <parent>base</parent>
            <child>lidar</child>
            <pose>-0.012 0 0.13 0 0 0</pose>
            <axis>
                <xyz>0 0 1</xyz>
                <use_parent_model_frame>true</use_parent_model_frame>
            </axis>
        </joint>

        <joint name="joint1_left_joint" type="revolute">
            <parent>base</parent>
            <child>joint1_left</child>
            <!--pose rpy can change xyz-->
            <pose>-0.11 -0.135 0.1 0 0 0</pose>
            <axis>
                <xyz>0 1 0</xyz>
            </axis>
        </joint>

        <joint name="joint1_right_joint" type="revolute">
            <parent>base</parent>
            <child>joint1_right</child>
            <pose>-0.11 0.135 0.1 0 0 0</pose>
            <axis>
                <xyz>0 1 0</xyz>
            </axis>
        </joint>

        <joint name="link1_left_joint" type="revolute">
            <parent>joint1_left</parent>
            <child>link1_left</child>
            <pose>-0.11 -0.135 0.1 0 0 0</pose>
            <axis>
                <xyz>0 1 0</xyz>
            </axis>
        </joint>

        <joint name="link1_right_joint" type="revolute">
            <parent>joint1_right</parent>
            <child>link1_right</child>
            <pose>-0.11 0.135 0.1 0 0 0</pose>
            <axis>
                <xyz>0 1 0</xyz>
            </axis>
        </joint>

        <joint name="joint2_left_joint" type="revolute">
            <parent>link1_left</parent>
            <child>joint2_left</child>
            <pose>-0.21 -0.135 0.1 0 0 0</pose>
            <axis>
                <xyz>0 1 0</xyz>
            </axis>
        </joint>

        <joint name="joint2_right_joint" type="revolute">
            <parent>link1_right</parent>
            <child>joint2_right</child>
            <pose>-0.21 0.135 0.1 0 0 0</pose>
            <axis>
                <xyz>0 1 0</xyz>
            </axis>
        </joint>

        <joint name="link2_left_joint" type="revolute">
            <parent>joint2_left</parent>
            <child>link2_left</child>
            <pose>-0.21 -0.135 0.1 0 0 0</pose>
            <axis>
                <xyz>0 1 0</xyz>
            </axis>
        </joint>

        <joint name="link2_right_joint" type="revolute">
            <parent>joint2_right</parent>
            <child>link2_right</child>
            <pose>-0.21 0.135 0.1 0 0 0</pose>
            <axis>
                <xyz>0 1 0</xyz>
            </axis>
        </joint>
    </model>
</sdf>